<?xml version="1.0"?>
<robot name="robotic_arm">
    <!-- Base Link -->
    <link name="base_link">
        <visual>
            <origin xyz="0 0 0.0425"/>  <!-- Half of the height to center the visual -->
            <geometry>
                <box size="0.06 0.045 0.085"/>
            </geometry>
            <material name="blue">
                <color rgba="0 0 1 1"/>  <!-- Blue -->
            </material>
        </visual>
        <collision>
            <origin xyz="0 0 0.0425"/>
            <geometry>
                <box size="0.06 0.045 0.085"/>
            </geometry>
        </collision>
    </link>

    <!-- Link 1  C_like_link -->
    <link name="link1">
        <visual>
            <origin xyz="0 0 0.0135"/>  <!-- Half of the height to center the visual -->
            <geometry>
                <box size="0.0598 0.022 0.027"/>
            </geometry>
            <material name="blue2">
                <color rgba="0 0 1 1"/>  <!-- Blue -->
            </material>
        </visual>
        <collision>
            <origin xyz="0 0 0.0135"/>
            <geometry>
                <box size="0.0598 0.022 0.027"/>
            </geometry>
        </collision>
    </link>

    <!-- Link 2   rotation_link-->
    <link name="link2">
        <visual>
            <origin xyz="0 0 0.04625"/>  <!-- Half of the height to center the visual -->
            <geometry>
                <box size="0.062 0.022 0.0925"/>
            </geometry>
            <material name="red">
                <color rgba="1 0 0 1"/>  <!-- Red -->
            </material>
        </visual>
        <collision>
            <origin xyz="0 0 0.04625"/>
            <geometry>
                <box size="0.062 0.022 0.0925"/>
            </geometry>
        </collision>
    </link>

    <!-- Link 3 C_like_link-->
    <link name="link3">
        <visual>
            <origin xyz="0 0 0.0135"/>  <!-- Half of the height to center the visual -->
            <geometry>
                <box size="0.062 0.042 0.027"/>
            </geometry>
            <material name="green">
                <color rgba="0 1 0 1"/>  <!-- Green -->
            </material>
        </visual>
        <collision>
            <origin xyz="0 0 0.0135"/>
            <geometry>
                <box size="0.062 0.042 0.027"/>
            </geometry>
        </collision>
    </link>

    <!-- Link 4 rotation_link-->
    <link name="link4">
        <visual>
            <origin xyz="0 0 0.04625"/>  <!-- Half of the height to center the visual -->
            <geometry>
                <box size="0.062 0.022 0.0925"/>
            </geometry>
            <material name="red">
                <color rgba="1 0 0 1"/>  <!-- Red -->
            </material>
        </visual>
        <collision>
            <origin xyz="0 0 0.04625"/>
            <geometry>
                <box size="0.062 0.022 0.0925"/>
            </geometry>
        </collision>
    </link>

    <!-- Link 5 C_like_link-->
    <link name="link5">
        <visual>
            <origin xyz="0 0 0.0135"/>  <!-- Half of the height to center the visual -->
            <geometry>
                <box size="0.062 0.042 0.027"/>
            </geometry>
            <material name="green">
                <color rgba="0 1 0 1"/>  <!-- Green -->
            </material>
        </visual>
        <collision>
            <origin xyz="0 0 0.0135"/>
            <geometry>
                <box size="0.062 0.042 0.027"/>
            </geometry>
        </collision>
    </link>

    <!-- Link 6 gripper_base-->
    <link name="link6">
        <visual>
            <origin xyz="0 0 0.0375"/>  <!-- Half of the height to center the visual -->
            <geometry>
                <box size="0.062 0.022 0.075"/>
            </geometry>
            <material name="red">
                <color rgba="1 0 0 1"/>  <!-- Red -->
            </material>
        </visual>
        <collision>
            <origin xyz="0 0 0.0375"/>
            <geometry>
                <box size="0.062 0.022 0.075"/>
            </geometry>
        </collision>
    </link>

    <!-- Link Grabber -->
    <link name="link_grabber">
        <visual>
            <origin xyz="0 0 0"/>  <!-- Half of the height to center the visual -->
            <geometry>
                <box size="0.062 0.022 0.03"/>
            </geometry>
            <material name="yellow">
                <color rgba="1 1 0 1"/>  <!-- Yellow -->
            </material>
        </visual>
        <collision>
            <origin xyz="0 0 0"/>
            <geometry>
                <box size="0.062 0.022 0.03"/>
            </geometry>
        </collision>
    </link>

    <!-- Fixed Part of the Clamp -->
    <link name="clamp_fixed">
        <visual>
            <origin xyz="0 0 0" rpy="0 0 0"/>  <!-- Rotated 45 degrees around X-axis -->
            <geometry>
                <box size="0.05 0.01 0.05"/>
            </geometry>
            <material name="gray">
                <color rgba="0.5 0.5 0.5 1"/>  <!-- Gray -->
            </material>
        </visual>
        <collision>
            <origin xyz="0 0 0" rpy="0 0 0"/>  <!-- Rotated 45 degrees around X-axis -->
            <geometry>
                <box size="0.05 0.01 0.05"/>
            </geometry>
        </collision>
    </link>

    <!-- Moving Part of the Clamp -->
    <link name="clamp_moving">
        <visual>
            <origin xyz="0 0 0"/>  <!-- Half of the height to center the visual -->
            <geometry>
                <box size="0.05 0.01 0.05"/>
            </geometry>
            <material name="dark_gray">
                <color rgba="0.3 0.3 0.3 1"/>  <!-- Dark Gray -->
            </material>
        </visual>
        <collision>
            <origin xyz="0 0 0"/>
            <geometry>
                <box size="0.05 0.01 0.05"/>
            </geometry>
        </collision>
    </link>

    <!-- Joint Definitions -->
    <joint name="rotating_base" type="revolute">
        <parent link="base_link"/>
        <child link="link1"/>
        <origin xyz="0 0 0.085" rpy="0 0 0"/>  <!-- Distance from world frame to first rotating joint -->
        <axis xyz="0 0 1"/>
        <limit effort="1.0" lower="-1.5708" upper="1.5708" velocity="1.0"/>
    </joint>

    <joint name="joint1" type="revolute">
        <parent link="link1"/>
        <child link="link2"/>
        <origin xyz="0 0 0.027" rpy="0 0 0"/>  <!-- Distance from base of link1 to where joint2 rotates -->
        <axis xyz="1 0 0"/>
        <limit effort="1.0" lower="-1.5708" upper="1.5708" velocity="1.0"/>
    </joint>

    <joint name="joint2" type="revolute">
        <parent link="link2"/>
        <child link="link3"/>
        <origin xyz="0 0 0.0925" rpy="0 0 0"/>  <!-- Distance from joint2 to where joint3 rotates -->
        <axis xyz="0 0 1"/>
        <limit effort="1.0" lower="-1.5708" upper="1.5708" velocity="1.0"/>
    </joint>

    <joint name="joint3" type="revolute">
        <parent link="link3"/>
        <child link="link4"/>
        <origin xyz="0 0 0.027" rpy="0 0 0"/>  <!-- Distance from joint3 to where joint4 rotates -->
        <axis xyz="1 0 0"/>
        <limit effort="1.0" lower="-1.97222" upper="1.97222" velocity="1.0"/>
    </joint>

    <joint name="joint4" type="revolute">
        <parent link="link4"/>
        <child link="link5"/>
        <origin xyz="0 0 0.0925" rpy="0 0 0"/>  <!-- Distance from joint4 to where joint5 rotates -->
        <axis xyz="0 0 1"/>
        <limit effort="1.0" lower="-1.5708" upper="1.5708" velocity="1.0"/>
    </joint>

    <joint name="joint5" type="revolute">
        <parent link="link5"/>
        <child link="link6"/>
        <origin xyz="0 0 0.027" rpy="0 0 0"/>  <!-- Distance from joint5 to where joint6 rotates -->
        <axis xyz="1 0 0"/>
        <limit effort="1.0" lower="-1.5708" upper="1.5708" velocity="1.0"/>
    </joint>

    <joint name="joint6" type="revolute">
        <parent link="link6"/>
        <child link="link_grabber"/>
        <origin xyz="0 0 0.075" rpy="0 0 0"/>  <!-- Distance from joint6 to grabber -->
        <axis xyz="0 0 1"/>
        <limit effort="1.0" lower="-1.5708" upper="1.5708" velocity="1.0"/>
    </joint>

    <!-- Fixed Clamp Joint -->
    <joint name="clamp_fixed_joint" type="fixed">
        <parent link="link_grabber"/>
        <child link="clamp_fixed"/>
        <origin xyz="0 0.03 0.04" rpy="0 0 0"/>  <!-- Position relative to link_grabber -->
    </joint>

    <!-- Moving Clamp Joint -->
    <joint name="clamp_moving_joint" type="revolute">
        <parent link="link_grabber"/>
        <child link="clamp_moving"/>
        <origin xyz="0 -0.03 0.04" rpy="0 0 0"/>  <!-- Position relative to link_grabber -->
        <axis xyz="1 0 0"/>  <!-- Rotates around the X-axis -->
        <limit effort="1.0" lower="-0.7854" upper="0.7854" velocity="1.0"/>  <!-- -45 to +45 degrees -->
    </joint>
</robot>
